[INFO] Module GCC/9.4.0 loaded.

Inactive Modules:
  1) UCX/1.17.0     2) numactl/2.0.16

The following have been reloaded with a version change:
  1) GCCcore/.11.3.0 => GCCcore/.9.4.0     3) zlib/1.2.13 => zlib/1.2.11
  2) binutils/2.38 => binutils/2.36.1

[INFO] Module CUDA/11.8.0 loaded.
[INFO] Module cuDNN/8.6.0.163-CUDA-11.8.0 loaded.
TypeError: expected dtype object, got 'numpy.dtypes.Float32DType'

The above exception was the direct cause of the following exception:

Traceback (most recent call last):
  File "/home/md334167/elzerman-with-unet/simulate_elzerman_data.py", line 521, in <module>
    main()
  File "/home/md334167/elzerman-with-unet/simulate_elzerman_data.py", line 370, in main
    _, mask, trace = generate_elzerman_signal([lambda_in, lambda_out, lambda_flip], [t_L, t_W, t_R, t_U], voltages, 1,n_samples_tot, signal_amp)
                     ^^^^^^^^^^^^^^^^^^^^^^^^^^^^^^^^^^^^^^^^^^^^^^^^^^^^^^^^^^^^^^^^^^^^^^^^^^^^^^^^^^^^^^^^^^^^^^^^^^^^^^^^^^^^^^^^^^^^^^^^^^^
SystemError: CPUDispatcher(<function generate_elzerman_signal at 0x14ac7b851d00>) returned a result with an exception set
