[INFO] Module GCC/9.4.0 loaded.

Inactive Modules:
  1) UCX/1.17.0     2) numactl/2.0.16

The following have been reloaded with a version change:
  1) GCCcore/.11.3.0 => GCCcore/.9.4.0     3) zlib/1.2.13 => zlib/1.2.11
  2) binutils/2.38 => binutils/2.36.1

[INFO] Module CUDA/11.8.0 loaded.
[INFO] Module cuDNN/8.6.0.163-CUDA-11.8.0 loaded.
Traceback (most recent call last):
  File "/home/md334167/elzerman-with-unet/train_for_exdata.py", line 327, in <module>
    main()
  File "/home/md334167/elzerman-with-unet/train_for_exdata.py", line 54, in main
    hdf5Data_noise.set_traces_dt() # self.data.set_traces_dt()
    ^^^^^^^^^^^^^^^^^^^^^^^^^^^^^^
  File "/rwthfs/rz/cluster/home/md334167/elzerman-with-unet/HDF5Data.py", line 396, in set_traces_dt
    self.traces_dt = self.file['Traces']['Alazar Slytherin - Ch1 - Data_t0dt'][0][1]
                     ~~~~~~~~~^^^^^^^^^^
  File "h5py/_objects.pyx", line 54, in h5py._objects.with_phil.wrapper
  File "h5py/_objects.pyx", line 55, in h5py._objects.with_phil.wrapper
  File "/home/md334167/miniconda3/envs/DL/lib/python3.11/site-packages/h5py/_hl/group.py", line 357, in __getitem__
    oid = h5o.open(self.id, self._e(name), lapl=self._lapl)
          ^^^^^^^^^^^^^^^^^^^^^^^^^^^^^^^^^^^^^^^^^^^^^^^^^
  File "h5py/_objects.pyx", line 54, in h5py._objects.with_phil.wrapper
  File "h5py/_objects.pyx", line 55, in h5py._objects.with_phil.wrapper
  File "h5py/h5o.pyx", line 241, in h5py.h5o.open
KeyError: "Unable to synchronously open object (object 'Traces' doesn't exist)"
